tests/messagesTest.csv
A,4697,0,0,1,S,12,LFC     ,15
A,4697,0,1,2,S,11,LFC     ,25
A,4697,0,2,3,S,34,LFC     ,33
A,4697,0,3,4,B,7,LFC     ,12
A,4697,0,4,5,B,4,LFC     ,3
F,6913,0,34200004838033,249426,B,100,SDOG    ,39,CDRG
U,836,0,28860654859429,46482,46496,143,49.6
D,8007,0,28802131843697,45785
X,3322,0,28808433086590,45911,10000
E,8186,2,28992128691417,48993,200,17332
S,0,0,11167869925131,O
